<?xml version="1.0"?>
<robot name="visual">

  <material name="blue">
    <color rgba="0 0 2 1"/>
  </material>
  <material name="black">
    <color rgba="0 0 0 1"/>
  </material>
  <material name="white">
    <color rgba="1 1 1 1"/>
  </material>

  <link name="base_link">
    <visual>
      <geometry>
        <box size="0.6 0.4 0.2"/>
      </geometry>
      <material name="blue"/>
    </visual>

  <joint name="base_link_sweavel" type="continuous">
    <axis xyz="0 0 1"/>
    <origin xyz="0.133333333333 0.2 -0.085"/>
    <parent link="right_front_wheel"/>
    <child link="base_link"/>
  </joint>
   <collision>
      <geometry>
        <box size="0.6 0.4 0.2"/>
      </geometry>
    </collision>
   <inertial>
      <mass value="10"/>
      <inertia ixx="0.4" ixy="0.0" ixz="0.0" iyy="0.4" iyz="0.0" izz="0.2"/>
    </inertial>
  </link>


  <link name="right_front_wheel">
    <visual>
      <origin rpy="1.57075 0 0" xyz="0 0 0"/>
      <geometry>
        <cylinder length="0.1" radius="0.095"/>
      </geometry>
      <material name="black"/>
    </visual>
  </link>
  <joint name="right_front_wheel_joint" type="continuous">
    <axis xyz="1 0 1"/>
    <origin xyz="0.133333333333 0.2 -0.085"/>
    <parent link="base_link"/>
    <child link="right_front_wheel"/>
  </joint>

  <link name="right_back_wheel">
    <visual>
      <origin rpy="1.57075 0 0" xyz="0 0 0"/>
      <geometry>
        <cylinder length="0.1" radius="0.095"/>
      </geometry>
      <material name="black"/>
    </visual>
  </link>
  <joint name="right_back_wheel_joint" type="continuous">
    <axis xyz="1 0 1"/>
    <origin xyz="-0.133333333333 0.2 -0.085"/>
    <parent link="base_link"/>
    <child link="right_back_wheel"/>
  </joint>


  <link name="left_front_wheel">
    <visual>
      <origin rpy="1.57075 0 0" xyz="0 0 0"/>
      <geometry>
        <cylinder length="0.1" radius="0.095"/>
      </geometry>
      <material name="black"/>
    </visual>
  </link>
  <joint name="left_front_wheel_joint" type="continuous">
   <axis xyz="1 0 1"/>
    <origin xyz="0.133333333333 -0.2 -0.085"/>
    <parent link="base_link"/>
    <child link="left_front_wheel"/>
  </joint>

  <link name="left_back_wheel">
    <visual>
      <origin rpy="1.57075 0 0" xyz="0 0 0"/>
      <geometry>
        <cylinder length="0.1" radius="0.095"/>
      </geometry>
      <material name="black"/>
    </visual>
  </link>
  <joint name="left_back_wheel_joint" type="continuous">
    <axis xyz="1 0 1"/>
    <origin xyz="-0.133333333333 -0.2 -0.085"/>
    <parent link="base_link"/>
    <child link="left_back_wheel"/>
  </joint>


</robot>
